<?xml version="1.0"?>
<sdf version='1.10'>
  <world name='empty'>
    <physics name='1ms' type='ignored'>
      <max_step_size>0.001</max_step_size>
      <real_time_factor>1</real_time_factor>
      <real_time_update_rate>1000</real_time_update_rate>
    </physics>
    <plugin name='gz::sim::systems::Physics' filename='gz-sim-physics-system'/>
    <plugin name='gz::sim::systems::UserCommands' filename='gz-sim-user-commands-system'/>
    <plugin name='gz::sim::systems::SceneBroadcaster' filename='gz-sim-scene-broadcaster-system'/>
    <plugin name='gz::sim::systems::Contact' filename='gz-sim-contact-system'/>
    <plugin name='gz::sim::systems::Sensors' filename='gz-sim-sensors-system'/>
    
    <gravity>0 0 -9.8</gravity>
    <magnetic_field>5.56e-06 2.28e-05 -4.23e-05</magnetic_field>
    <atmosphere type='adiabatic'/>
    <scene>
      <ambient>0.4 0.4 0.4 1</ambient>
      <background>0.7 0.7 0.7 1</background>
      <shadows>true</shadows>
    </scene>

    <!-- ground unchanged -->
    <model name='ground_plane'>
      <static>true</static>
      <link name='link'>
        <collision name='collision'>
          <geometry>
            <plane>
              <normal>0 0 1</normal>
              <size>100 100</size>
            </plane>
          </geometry>
        </collision>
        <visual name='visual'>
          <geometry>
            <plane>
              <normal>0 0 1</normal>
              <size>100 100</size>
            </plane>
          </geometry>
          <material>
            <ambient>0.8 0.8 0.8 1</ambient>
            <diffuse>0.8 0.8 0.8 1</diffuse>
            <specular>0.8 0.8 0.8 1</specular>
          </material>
        </visual>
      </link>
    </model>

    <model name='wall_north'>
      <static>true</static>
      <pose>0 10 1 0 0 0</pose>
      <link name='link'>
        <visual name='visual'>
          <geometry><box><size>20 0.3 2</size></box></geometry>
          <material>
            <ambient>0.7 0.7 0.7 1</ambient>
            <diffuse>0.7 0.7 0.7 1</diffuse>
            <specular>0.1 0.1 0.1 1</specular>
          </material>
        </visual>
        <collision name='collision'>
          <geometry><box><size>20 0.3 2</size></box></geometry>
        </collision>
      </link>
    </model>

    <model name='wall_south'>
      <static>true</static>
      <pose>0 -10 1 0 0 0</pose>
      <link name='link'>
        <visual name='visual'>
          <geometry><box><size>20 0.3 2</size></box></geometry>
          <material>
            <ambient>0.7 0.7 0.7 1</ambient>
            <diffuse>0.7 0.7 0.7 1</diffuse>
            <specular>0.1 0.1 0.1 1</specular>
          </material>
        </visual>
        <collision name='collision'>
          <geometry><box><size>20 0.3 2</size></box></geometry>
        </collision>
      </link>
    </model>

    <model name='wall_east'>
      <static>true</static>
      <pose>10 0 1 0 0 0</pose>
      <link name='link'>
        <visual name='visual'>
          <geometry><box><size>0.3 20 2</size></box></geometry>
          <material>
            <ambient>0.7 0.7 0.7 1</ambient>
            <diffuse>0.7 0.7 0.7 1</diffuse>
            <specular>0.1 0.1 0.1 1</specular>
          </material>
        </visual>
        <collision name='collision'>
          <geometry><box><size>0.3 20 2</size></box></geometry>
        </collision>
      </link>
    </model>

    <model name='wall_west'>
      <static>true</static>
      <pose>-10 0 1 0 0 0</pose>
      <link name='link'>
        <visual name='visual'>
          <geometry><box><size>0.3 20 2</size></box></geometry>
          <material>
            <ambient>0.7 0.7 0.7 1</ambient>
            <diffuse>0.7 0.7 0.7 1</diffuse>
            <specular>0.1 0.1 0.1 1</specular>
          </material>
        </visual>
        <collision name='collision'>
          <geometry><box><size>0.3 20 2</size></box></geometry>
        </collision>
      </link>
    </model>

    <model name='inner_wall_1'>
      <static>true</static>
      <pose>0 0 1 0 0 0</pose>
      <link name='link'>
        <visual name='visual'>
          <geometry><box><size>8 0.3 2</size></box></geometry>
          <material>
            <ambient>0.7 0.7 0.7 1</ambient>
            <diffuse>0.7 0.7 0.7 1</diffuse>
            <specular>0.1 0.1 0.1 1</specular>
          </material>
        </visual>
        <collision name='collision'>
          <geometry><box><size>8 0.3 2</size></box></geometry>
        </collision>
      </link>
    </model>

    <model name='inner_wall_2'>
      <static>true</static>
      <pose>3 6.76747 1 0 0 0</pose>
      <link name='link'>
        <visual name='visual'>
          <geometry><box><size>0.3 6 2</size></box></geometry>
          <material>
            <ambient>0.7 0.7 0.7 1</ambient>
            <diffuse>0.7 0.7 0.7 1</diffuse>
            <specular>0.1 0.1 0.1 1</specular>
          </material>
        </visual>
        <collision name='collision'>
          <geometry><box><size>0.3 6 2</size></box></geometry>
        </collision>
      </link>
    </model>

    <model name='inner_wall_3'>
      <static>true</static>
      <pose>-1.0469 -8.58647 1 0 0 0.6</pose>
      <link name='link'>
        <visual name='visual'>
          <geometry><box><size>4 0.25 2</size></box></geometry>
          <material>
            <ambient>0.7 0.7 0.7 1</ambient>
            <diffuse>0.7 0.7 0.7 1</diffuse>
            <specular>0.1 0.1 0.1 1</specular>
          </material>
        </visual>
        <collision name='collision'>
          <geometry><box><size>4 0.25 2</size></box></geometry>
        </collision>
      </link>
    </model>


    <model name='aruco_box'>
      <pose>-9.0 9.0 1.0 0 0 -0.70</pose>
      <link name="box_link">
        <inertial>
          <mass>10.0</mass>
          <inertia> <ixx>1.66</ixx><ixy>0</ixy><ixz>0</ixz>
            <iyy>1.66</iyy><iyz>0</iyz>
            <izz>1.66</izz>
          </inertia>
        </inertial>
        <visual name="visual">
          <geometry><box><size>1.0 1.0 1.0</size></box></geometry>
          <material><ambient>1 1 1 1</ambient><diffuse>1 1 1 1</diffuse></material>
        </visual>
        <collision name="collision">
          <geometry><box><size>1.0 1.0 1.0</size></box></geometry>
        </collision>
      </link>
      <include>
        <uri>model://aruco_marker_0</uri>
        <name>marker_0</name>
        <pose>0.51 0 0 3.14159 1.5707 0</pose>
      </include>
      <joint name="joint_0" type="fixed">
        <parent>box_link</parent>
        <child>marker_0::link</child>
      </joint>
    </model>

    <model name='aruco_box_1'>
      <pose>9.0 9.0 1.0 0 0 -2.30</pose>
      <link name="box_link">
        <inertial>
          <mass>10.0</mass>
          <inertia>
            <ixx>1.66</ixx><ixy>0</ixy><ixz>0</ixz>
            <iyy>1.66</iyy><iyz>0</iyz>
            <izz>1.66</izz>
          </inertia>
        </inertial>
        <visual name="visual">
          <geometry><box><size>1.0 1.0 1.0</size></box></geometry>
          <material><ambient>1 1 1 1</ambient><diffuse>1 1 1 1</diffuse></material>
        </visual>
        <collision name="collision">
          <geometry><box><size>1.0 1.0 1.0</size></box></geometry>
        </collision>
      </link>
      <include>
        <uri>model://aruco_marker_1</uri>
        <name>marker_1</name>
        <pose>0.51 0 0 3.14159 1.5707 0</pose>
      </include>
      <joint name="joint_1" type="fixed">
        <parent>box_link</parent>
        <child>marker_1::link</child>
      </joint>
    </model>

    <model name='aruco_box_2'>
      <pose>9.0 -9.0 1.0 0 0 2.30</pose>
      <link name="box_link">
        <inertial>
          <mass>10.0</mass>
          <inertia>
            <ixx>1.66</ixx><ixy>0</ixy><ixz>0</ixz>
            <iyy>1.66</iyy><iyz>0</iyz>
            <izz>1.66</izz>
          </inertia>
        </inertial>
        <visual name="visual">
          <geometry><box><size>1.0 1.0 1.0</size></box></geometry>
          <material><ambient>1 1 1 1</ambient><diffuse>1 1 1 1</diffuse></material>
        </visual>
        <collision name="collision">
          <geometry><box><size>1.0 1.0 1.0</size></box></geometry>
        </collision>
      </link>
      <include>
        <uri>model://aruco_marker_2</uri>
        <name>marker_2</name>
        <pose>0.51 0 0 3.14159 1.5707 0</pose>
      </include>
      <joint name="joint_2" type="fixed">
        <parent>box_link</parent>
        <child>marker_2::link</child>
      </joint>
    </model>

    <model name='aruco_box_3'>
      <pose>-9.0 -9.0 1.0 0 0 0.70</pose>
      <link name="box_link">
        <inertial>
          <mass>10.0</mass>
          <inertia>
            <ixx>1.66</ixx><ixy>0</ixy><ixz>0</ixz>
            <iyy>1.66</iyy><iyz>0</iyz>
            <izz>1.66</izz>
          </inertia>
        </inertial>
        <visual name="visual">
          <geometry><box><size>1.0 1.0 1.0</size></box></geometry>
          <material><ambient>1 1 1 1</ambient><diffuse>1 1 1 1</diffuse></material>
        </visual>
        <collision name="collision">
          <geometry><box><size>1.0 1.0 1.0</size></box></geometry>
        </collision>
      </link>
      <include>
        <uri>model://aruco_marker_3</uri>
        <name>marker_3</name>
        <pose>0.51 0 0 3.14159 1.5707 0</pose>
      </include>
      <joint name="joint_3" type="fixed">
        <parent>box_link</parent>
        <child>marker_3::link</child>
      </joint>
    </model>

    <light name='sun' type='directional'>
      <pose>0 0 10 0 0 0</pose>
      <direction>-0.5 0.1 -0.9</direction>
      <diffuse>0.8 0.8 0.8 1</diffuse>
      <specular>0.2 0.2 0.2 1</specular>
    </light>
    
    <model name='blueCar'>
      <pose relative_to='world'>8 8 0 0 0 180</pose>
      <link name='chassis'>
        <pose relative_to='__model__'>0.5 0 0.4 0 0 0</pose>
        <inertial>
          <mass>1.14395</mass>
          <inertia>
            <ixx>0.095329</ixx>
            <ixy>0</ixy>
            <ixz>0</ixz>
            <iyy>0.381317</iyy>
            <iyz>0</iyz>
            <izz>0.476646</izz>
          </inertia>
        </inertial>
        <visual name='visual'>
          <geometry>
            <box>
              <size>2.0 1.0 0.5</size>
            </box>
          </geometry>
          <material>
            <ambient>0.0 0.0 1.0 1</ambient>
            <diffuse>0.0 0.0 1.0 1</diffuse>
            <specular>0.0 0.0 1.0 1</specular>
          </material>
        </visual>
        <collision name='collision'>
          <geometry>
              <box>
                <size>2.0 1.0 0.5</size>
              </box>
          </geometry>
        </collision>
    
        <sensor name="imu_sensor" type="imu">
          <always_on>1</always_on>
          <update_rate>100</update_rate>
          <visualize>true</visualize>
          <topic>imu</topic>
        </sensor>

        <sensor name='gpu_lidar' type='gpu_lidar'> <pose relative_to='lidar_frame'>0 0 0 0 0 0</pose>
          <topic>lidar</topic>
          <update_rate>10</update_rate>
          <ray>
            <scan>
              <horizontal>
                <samples>640</samples>
                <resolution>1</resolution>
                <min_angle>-1.396263</min_angle>
                <max_angle>1.396263</max_angle>
              </horizontal>
              <vertical>
                <samples>1</samples>
                <resolution>0.01</resolution>
                <min_angle>0</min_angle>
                <max_angle>0</max_angle>
              </vertical>
            </scan>
            <range>
              <min>0.08</min>
              <max>10.0</max>
              <resolution>0.01</resolution>
            </range>
          </ray>
          <always_on>1</always_on>
          <visualize>true</visualize>
        </sensor>
      </link> 

      <link name='left_wheel'>
        <pose relative_to="chassis">-0.5 0.6 0 -1.5707 0 0</pose>
        <inertial>
          <mass>1</mass>
          <inertia>
            <ixx>0.043333</ixx>
            <ixy>0</ixy>
            <ixz>0</ixz>
            <iyy>0.043333</iyy>
            <iyz>0</iyz>
            <izz>0.08</izz>
          </inertia>
        </inertial>
        <visual name='visual'>
          <geometry>
            <cylinder>
                <radius>0.4</radius>
                <length>0.2</length>
            </cylinder>
          </geometry>
          <material>
            <ambient>1.0 0.0 0.0 1</ambient>
            <diffuse>1.0 0.0 0.0 1</diffuse>
            <specular>1.0 0.0 0.0 1</specular>
          </material>
        </visual>
        <collision name='collision'>
          <geometry>
            <cylinder>
              <radius>0.4</radius>
              <length>0.2</length>
            </cylinder>
          </geometry>
        </collision>
      </link>

      <link name='right_wheel'>
        <pose relative_to="chassis">-0.5 -0.6 0 -1.5707 0 0</pose>
        <inertial>
          <mass>1</mass>
          <inertia>
            <ixx>0.043333</ixx>
            <ixy>0</ixy>
            <ixz>0</ixz>
            <iyy>0.043333</iyy>
            <iyz>0</iyz>
            <izz>0.08</izz>
          </inertia>
        </inertial>
        <visual name='visual'>
          <geometry>
            <cylinder>
              <radius>0.4</radius>
              <length>0.2</length>
            </cylinder>
          </geometry>
          <material>
            <ambient>1.0 0.0 0.0 1</ambient>
            <diffuse>1.0 0.0 0.0 1</diffuse>
            <specular>1.0 0.0 0.0 1</specular>
          </material>
        </visual>
        <collision name='collision'>
          <geometry>
            <cylinder>
              <radius>0.4</radius>
              <length>0.2</length>
            </cylinder>
          </geometry>
        </collision>
      </link>

      <link name='caster'>
        <pose relative_to='caster_frame'/>
        <inertial>
          <mass>1</mass>
          <inertia>
            <ixx>0.016</ixx>
            <ixy>0</ixy>
            <ixz>0</ixz>
            <iyy>0.016</iyy>
            <iyz>0</iyz>
            <izz>0.016</izz>
          </inertia>
        </inertial>
        <visual name='visual'>
          <geometry>
            <sphere>
              <radius>0.2</radius>
            </sphere>
          </geometry>
          <material>
            <ambient>1.0 0 0.0 1</ambient>
            <diffuse>1.0 0 0.0 1</diffuse>
            <specular>1.0 0 0.0 1</specular>
          </material>
        </visual>
        <collision name='collision'>
          <geometry>
            <sphere>
              <radius>0.2</radius>
            </sphere>
          </geometry>
        </collision>
      </link>

      <link name="cameraMIA">
        <pose relative_to="camera_frame">0 0 0 0 0 0</pose>
        <inertial>
          <mass>0.1</mass>
          <inertia>
            <ixx>0.0001</ixx>
            <ixy>0</ixy>
            <ixz>0</ixz>
            <iyy>0.0001</iyy>
            <iyz>0</iyz>
            <izz>0.0001</izz>
          </inertia>
        </inertial>
        <visual name="visual">
          <geometry>
            <box>
              <size>0.1 0.25 0.1</size>
            </box>
          </geometry>
          <material>
            <ambient>1 0 0.0 1</ambient>
            <diffuse>1 0 0.0 1</diffuse>
            <specular>1.0 0.0 1</specular>
          </material>
        </visual>
        <collision name="collision">
          <geometry>
            <box>
              <size>0.1 0.25 0.1</size>
            </box>
          </geometry>
        </collision>
        <sensor type="camera" name="camera_sensor">
          <pose>0 0 0 0 0 0</pose>                
          <camera>
            <horizontal_fov>1.047</horizontal_fov>
            <image>
                <width>320</width>
                <height>240</height>
            </image>
            <clip>
              <near>0.1</near>
              <far>100</far>
            </clip>
            <camera_info_topic>camera/camera_info</camera_info_topic>
          </camera>
          <always_on>1</always_on>
          <update_rate>30</update_rate>
          <visualize>true</visualize>
          <topic>camera/image</topic>
        </sensor>
      </link>

      <frame name="caster_frame" attached_to='chassis'>
        <pose>0.8 0 -0.2 0 0 0</pose>
      </frame>

      <frame name="camera_frame" attached_to='chassis'>
        <pose>0.9 0 0.30 0 0 0</pose> 
      </frame>

      <joint name='left_wheel_joint' type='revolute'>
        <pose relative_to='left_wheel'/>
        <parent>chassis</parent>
        <child>left_wheel</child>
        <axis>
          <xyz expressed_in='__model__'>0 1 0</xyz>
          <limit>
            <lower>-1.79769e+308</lower>
            <upper>1.79769e+308</upper>
          </limit>
        </axis>
      </joint>

      <joint name='right_wheel_joint' type='revolute'>
        <pose relative_to='right_wheel'/>
        <parent>chassis</parent>
        <child>right_wheel</child>
        <axis>
          <xyz expressed_in='__model__'>0 1 0</xyz>
          <limit>
            <lower>-1.79769e+308</lower>
            <upper>1.79769e+308</upper>
          </limit>
        </axis>
      </joint>

      <joint name='caster_wheel' type='ball'>
        <parent>chassis</parent>
        <child>caster</child>
      </joint>

      <joint name="camera_joint" type="revolute">  #OSS: TYPE REVOLUTE PERCHè ALMENO COSI /POSE MI DA LA POSIZIONE DELLA CAMERA RISPETTO AL ROBOT
        <pose relative_to='camera_frame'>0 0 0 0 0 0</pose>
        <parent>chassis</parent>
        <child>cameraMIA</child>
        <axis>
          <xyz expressed_in='__model__'>0 0 1</xyz>
          <limit>
            <lower>0.0</lower>
            <upper>0.0</upper>
          </limit>
        </axis>
      </joint>

      <plugin
        filename="gz-sim-diff-drive-system"
        name="gz::sim::systems::DiffDrive">
        <left_joint>left_wheel_joint</left_joint>
        <right_joint>right_wheel_joint</right_joint>
        <wheel_separation>1.2</wheel_separation>
        <wheel_radius>0.4</wheel_radius>
        <odom_publish_frequency>1</odom_publish_frequency>
        <topic>cmd_vel</topic>
      </plugin>

      <plugin
        filename="gz-sim-joint-state-publisher-system"
        name="gz::sim::systems::JointStatePublisher">
      </plugin>

      <plugin
        filename="gz-sim-pose-publisher-system"
        name="gz::sim::systems::PosePublisher">
        <publish_link_pose>true</publish_link_pose>
        <publish_sensor_pose>true</publish_sensor_pose>
        <publish_collision_pose>false</publish_collision_pose>
        <publish_visual_pose>false</publish_visual_pose>
        <publish_nested_model_pose>true</publish_nested_model_pose>
        <use_pose_vector_msg>true</use_pose_vector_msg>
        <static_publisher>true</static_publisher>
        <static_update_frequency>10</static_update_frequency>
      </plugin>
    </model>  
  </world>
</sdf>